Workbook

Sheet Dashboard
B2: BETON FİYAT HESAPLAMA PANELİ
B3: NASIL KULLANILIR? ① Sol taraftaki SARI kutulara güncel değerleri yazın. ② Kâr ve KDV oranlarını girin. ③ Fiyatlar sağ tarafta otomatik hesaplanır.
B5: Dönem | C5: EKİM | F5: 🔍 HIZLI FİYAT SORGULAMA — Listeden seçin, fiyat anında çıksın
F6: Üretim Tipi | H6: MİKSERLİ | J6: Maliyet (kârsız) | L6: =INDEX(Hesaplama!$C$45:$H$47,MATCH($H$6,Hesaplama!$B$45:$B$47,0),MATCH($H$7,Hesaplama!$C$23:$H$23,0)) -> 2723.2305
B7: ① GÜNCEL FİYATLAR (KDV hariç) | F7: Beton Sınıfı | H7: C 25 | J7: Satış Fiyatı (KDV hariç) | L7: =L6*(1+H8) -> 3131.715
B8: Çimento | C8: 4300 | D8: TL / ton | F8: Kâr Oranı | H8: 0.15 | J8: Satış Fiyatı (KDV dahil) | L8: =L7*(1+$C$34) -> 3758.058
B9: Agrega | C9: 200 | D9: TL / ton
B10: Katkı | C10: 0.62 | D10: $ / kg | F10: 📋 FİYAT LİSTESİ (TL / m³)
B11: Dolar Kuru | C11: 49.16 | D11: TL
B12: Mazot | C12: 94.995 | D12: TL / litre | F12: POMPALI | H12: Beton mikserle şantiyeye taşınır ve pompa ile dökülür.
B13: Elektrik | C13: 2.92 | D13: TL / kWh | F13: Beton Sınıfı | G13: Maliyet (kârsız) | H13: =$C$31 -> 0.1 | J13: =$C$32 -> 0.15 | L13: =$C$33 -> 0.2
B14: Su | C14: 12.175 | D14: TL / ton | H14: KDV Hariç | I14: KDV Dahil | J14: KDV Hariç | K14: KDV Dahil | L14: KDV Hariç | M14: KDV Dahil
B15: İşçi Maliyeti (Maaş + SGK) | C15: 70000 | D15: TL / kişi / ay | F15: C 16 | G15: =INDEX(Hesaplama!$C$45:$H$47,MATCH($F$12,Hesaplama!$B$45:$B$47,0),MATCH($F15,Hesaplama!$C$23:$H$23,0)) -> 2174.1514 | H15: =$G15*(1+H$13) -> 2391.5665 | I15: =H15*(1+$C$34) -> 2869.8798 | J15: =$G15*(1+J$13) -> 2500.2741 | K15: =J15*(1+$C$34) -> 3000.3289 | L15: =$G15*(1+L$13) -> 2608.9816 | M15: =L15*(1+$C$34) -> 3130.778
F16: C 20 | G16: =INDEX(Hesaplama!$C$45:$H$47,MATCH($F$12,Hesaplama!$B$45:$B$47,0),MATCH($F16,Hesaplama!$C$23:$H$23,0)) -> 2439.1856 | H16: =$G16*(1+H$13) -> 2683.1042 | I16: =H16*(1+$C$34) -> 3219.725 | J16: =$G16*(1+J$13) -> 2805.0635 | K16: =J16*(1+$C$34) -> 3366.0762 | L16: =$G16*(1+L$13) -> 2927.0228 | M16: =L16*(1+$C$34) -> 3512.4273
B17: ② İŞLETME BİLGİLERİ | F17: C 25 | G17: =INDEX(Hesaplama!$C$45:$H$47,MATCH($F$12,Hesaplama!$B$45:$B$47,0),MATCH($F17,Hesaplama!$C$23:$H$23,0)) -> 2796.0441 | H17: =$G17*(1+H$13) -> 3075.6485 | I17: =H17*(1+$C$34) -> 3690.7783 | J17: =$G17*(1+J$13) -> 3215.4507 | K17: =J17*(1+$C$34) -> 3858.5409 | L17: =$G17*(1+L$13) -> 3355.253 | M17: =L17*(1+$C$34) -> 4026.3035
B18: Ortalama Beton Döküm Mesafesi | C18: 24 | D18: km | F18: C 30 | G18: =INDEX(Hesaplama!$C$45:$H$47,MATCH($F$12,Hesaplama!$B$45:$B$47,0),MATCH($F18,Hesaplama!$C$23:$H$23,0)) -> 2977.1919 | H18: =$G18*(1+H$13) -> 3274.9111 | I18: =H18*(1+$C$34) -> 3929.8933 | J18: =$G18*(1+J$13) -> 3423.7707 | K18: =J18*(1+$C$34) -> 4108.5248 | L18: =$G18*(1+L$13) -> 3572.6303 | M18: =L18*(1+$C$34) -> 4287.1564
B19: Agrega Taşıma Mesafesi | C19: 21 | D19: km | F19: C 35 | G19: =INDEX(Hesaplama!$C$45:$H$47,MATCH($F$12,Hesaplama!$B$45:$B$47,0),MATCH($F19,Hesaplama!$C$23:$H$23,0)) -> 3113.6394 | H19: =$G19*(1+H$13) -> 3425.0033 | I19: =H19*(1+$C$34) -> 4110.0039 | J19: =$G19*(1+J$13) -> 3580.6853 | K19: =J19*(1+$C$34) -> 4296.8223 | L19: =$G19*(1+L$13) -> 3736.3672 | M19: =L19*(1+$C$34) -> 4483.6407
B20: Günlük Ortalama Beton Üretimi | C20: 140 | D20: m³ / gün | F20: C 40 | G20: =INDEX(Hesaplama!$C$45:$H$47,MATCH($F$12,Hesaplama!$B$45:$B$47,0),MATCH($F20,Hesaplama!$C$23:$H$23,0)) -> 3296.6121 | H20: =$G20*(1+H$13) -> 3626.2733 | I20: =H20*(1+$C$34) -> 4351.528 | J20: =$G20*(1+J$13) -> 3791.1039 | K20: =J20*(1+$C$34) -> 4549.3247 | L20: =$G20*(1+L$13) -> 3955.9346 | M20: =L20*(1+$C$34) -> 4747.1215
B21: Mikser Taşıma Kapasitesi | C21: 10 | D21: m³
B23: ③ AYLIK KİRA BEDELLERİ | F23: MİKSERLİ | H23: Beton mikserle şantiyeye taşınır, pompa kullanılmaz.
B24: Santral | C24: 0 | D24: TL / ay | F24: Beton Sınıfı | G24: Maliyet (kârsız) | H24: =$C$31 -> 0.1 | J24: =$C$32 -> 0.15 | L24: =$C$33 -> 0.2
B25: Mikser (araç başına) | C25: 0 | D25: TL / ay | H25: KDV Hariç | I25: KDV Dahil | J25: KDV Hariç | K25: KDV Dahil | L25: KDV Hariç | M25: KDV Dahil
B26: Pompa | C26: 0 | D26: TL / ay | F26: C 16 | G26: =INDEX(Hesaplama!$C$45:$H$47,MATCH($F$23,Hesaplama!$B$45:$B$47,0),MATCH($F26,Hesaplama!$C$23:$H$23,0)) -> 2101.3377 | H26: =$G26*(1+H$24) -> 2311.4715 | I26: =H26*(1+$C$34) -> 2773.7658 | J26: =$G26*(1+J$24) -> 2416.5384 | K26: =J26*(1+$C$34) -> 2899.846 | L26: =$G26*(1+L$24) -> 2521.6052 | M26: =L26*(1+$C$34) -> 3025.9263
B27: Loader | C27: 0 | D27: TL / ay | F27: C 20 | G27: =INDEX(Hesaplama!$C$45:$H$47,MATCH($F$23,Hesaplama!$B$45:$B$47,0),MATCH($F27,Hesaplama!$C$23:$H$23,0)) -> 2366.372 | H27: =$G27*(1+H$24) -> 2603.0092 | I27: =H27*(1+$C$34) -> 3123.611 | J27: =$G27*(1+J$24) -> 2721.3278 | K27: =J27*(1+$C$34) -> 3265.5933 | L27: =$G27*(1+L$24) -> 2839.6464 | M27: =L27*(1+$C$34) -> 3407.5756
B28: Servis Aracı | C28: 0 | D28: TL / ay | F28: C 25 | G28: =INDEX(Hesaplama!$C$45:$H$47,MATCH($F$23,Hesaplama!$B$45:$B$47,0),MATCH($F28,Hesaplama!$C$23:$H$23,0)) -> 2723.2305 | H28: =$G28*(1+H$24) -> 2995.5535 | I28: =H28*(1+$C$34) -> 3594.6642 | J28: =$G28*(1+J$24) -> 3131.715 | K28: =J28*(1+$C$34) -> 3758.058 | L28: =$G28*(1+L$24) -> 3267.8766 | M28: =L28*(1+$C$34) -> 3921.4519
F29: C 30 | G29: =INDEX(Hesaplama!$C$45:$H$47,MATCH($F$23,Hesaplama!$B$45:$B$47,0),MATCH($F29,Hesaplama!$C$23:$H$23,0)) -> 2904.3782 | H29: =$G29*(1+H$24) -> 3194.8161 | I29: =H29*(1+$C$34) -> 3833.7793 | J29: =$G29*(1+J$24) -> 3340.035 | K29: =J29*(1+$C$34) -> 4008.042 | L29: =$G29*(1+L$24) -> 3485.2539 | M29: =L29*(1+$C$34) -> 4182.3047
B30: ④ KÂR VE KDV ORANLARI | F30: C 35 | G30: =INDEX(Hesaplama!$C$45:$H$47,MATCH($F$23,Hesaplama!$B$45:$B$47,0),MATCH($F30,Hesaplama!$C$23:$H$23,0)) -> 3040.8257 | H30: =$G30*(1+H$24) -> 3344.9083 | I30: =H30*(1+$C$34) -> 4013.8899 | J30: =$G30*(1+J$24) -> 3496.9495 | K30: =J30*(1+$C$34) -> 4196.3394 | L30: =$G30*(1+L$24) -> 3648.9908 | M30: =L30*(1+$C$34) -> 4378.789
B31: Kâr Oranı 1 | C31: 0.1 | D31: % | F31: C 40 | G31: =INDEX(Hesaplama!$C$45:$H$47,MATCH($F$23,Hesaplama!$B$45:$B$47,0),MATCH($F31,Hesaplama!$C$23:$H$23,0)) -> 3223.7985 | H31: =$G31*(1+H$24) -> 3546.1783 | I31: =H31*(1+$C$34) -> 4255.414 | J31: =$G31*(1+J$24) -> 3707.3682 | K31: =J31*(1+$C$34) -> 4448.8419 | L31: =$G31*(1+L$24) -> 3868.5581 | M31: =L31*(1+$C$34) -> 4642.2698
B32: Kâr Oranı 2 | C32: 0.15 | D32: %
B33: Kâr Oranı 3 | C33: 0.2 | D33: %
B34: KDV Oranı | C34: 0.2 | D34: % | F34: SANTRAL ALTI | H34: Müşteri betonu santralden kendi aracıyla teslim alır.
F35: Beton Sınıfı | G35: Maliyet (kârsız) | H35: =$C$31 -> 0.1 | J35: =$C$32 -> 0.15 | L35: =$C$33 -> 0.2
B36: Sarı kutular = sizin gireceğiniz değerler. Diğer tüm hücreler otomatik hesaplanır. | H36: KDV Hariç | I36: KDV Dahil | J36: KDV Hariç | K36: KDV Dahil | L36: KDV Hariç | M36: KDV Dahil
F37: C 16 | G37: =INDEX(Hesaplama!$C$45:$H$47,MATCH($F$34,Hesaplama!$B$45:$B$47,0),MATCH($F37,Hesaplama!$C$23:$H$23,0)) -> 1766.1953 | H37: =$G37*(1+H$35) -> 1942.8149 | I37: =H37*(1+$C$34) -> 2331.3778 | J37: =$G37*(1+J$35) -> 2031.1246 | K37: =J37*(1+$C$34) -> 2437.3496 | L37: =$G37*(1+L$35) -> 2119.4344 | M37: =L37*(1+$C$34) -> 2543.3213
F38: C 20 | G38: =INDEX(Hesaplama!$C$45:$H$47,MATCH($F$34,Hesaplama!$B$45:$B$47,0),MATCH($F38,Hesaplama!$C$23:$H$23,0)) -> 2031.2296 | H38: =$G38*(1+H$35) -> 2234.3526 | I38: =H38*(1+$C$34) -> 2681.2231 | J38: =$G38*(1+J$35) -> 2335.914 | K38: =J38*(1+$C$34) -> 2803.0968 | L38: =$G38*(1+L$35) -> 2437.4755 | M38: =L38*(1+$C$34) -> 2924.9706
F39: C 25 | G39: =INDEX(Hesaplama!$C$45:$H$47,MATCH($F$34,Hesaplama!$B$45:$B$47,0),MATCH($F39,Hesaplama!$C$23:$H$23,0)) -> 2388.0881 | H39: =$G39*(1+H$35) -> 2626.8969 | I39: =H39*(1+$C$34) -> 3152.2763 | J39: =$G39*(1+J$35) -> 2746.3013 | K39: =J39*(1+$C$34) -> 3295.5616 | L39: =$G39*(1+L$35) -> 2865.7057 | M39: =L39*(1+$C$34) -> 3438.8469
F40: C 30 | G40: =INDEX(Hesaplama!$C$45:$H$47,MATCH($F$34,Hesaplama!$B$45:$B$47,0),MATCH($F40,Hesaplama!$C$23:$H$23,0)) -> 2569.2359 | H40: =$G40*(1+H$35) -> 2826.1595 | I40: =H40*(1+$C$34) -> 3391.3914 | J40: =$G40*(1+J$35) -> 2954.6213 | K40: =J40*(1+$C$34) -> 3545.5455 | L40: =$G40*(1+L$35) -> 3083.0831 | M40: =L40*(1+$C$34) -> 3699.6997
F41: C 35 | G41: =INDEX(Hesaplama!$C$45:$H$47,MATCH($F$34,Hesaplama!$B$45:$B$47,0),MATCH($F41,Hesaplama!$C$23:$H$23,0)) -> 2705.6833 | H41: =$G41*(1+H$35) -> 2976.2517 | I41: =H41*(1+$C$34) -> 3571.502 | J41: =$G41*(1+J$35) -> 3111.5358 | K41: =J41*(1+$C$34) -> 3733.843 | L41: =$G41*(1+L$35) -> 3246.82 | M41: =L41*(1+$C$34) -> 3896.184
F42: C 40 | G42: =INDEX(Hesaplama!$C$45:$H$47,MATCH($F$34,Hesaplama!$B$45:$B$47,0),MATCH($F42,Hesaplama!$C$23:$H$23,0)) -> 2888.6561 | H42: =$G42*(1+H$35) -> 3177.5217 | I42: =H42*(1+$C$34) -> 3813.026 | J42: =$G42*(1+J$35) -> 3321.9545 | K42: =J42*(1+$C$34) -> 3986.3454 | L42: =$G42*(1+L$35) -> 3466.3873 | M42: =L42*(1+$C$34) -> 4159.6648
F44: Tüm fiyatlar 1 m³ beton içindir ve TL cinsindendir. Kârsız maliyet; malzeme, nakliye, işçilik, enerji ve kira giderlerini içerir.

Sheet Beton Maliyet
B1: EKİM
B2: ÜRETİM TİPİ: | C2: POMPALI
C3: ÇİMENTO (KDV HARİÇ) | D3: AGREGA (KDV HARİÇ) | E3: KATKI (KDV HARİÇ) | F3: MAZOT (KDV HARİÇ) | G3: ORT. İŞÇİLİK (MAAŞ + SİGORTA | H3: DOLAR/TL | I3: ELEKTRİK KWH ÜCRETİ (KDV HARİÇ) | J3: ORT. BETON DÖKÜM MESAFESİ (KM) | K3: KAMYON AGREGA TAŞIMA MESAFESİ | L3: ORT. GÜNLÜK BETON DÖKÜMÜ | M3: SU FİYATI (KDV HARİÇ) | N3: ORT MİKSER TAŞIMA KAPASİTESİ
C4: 4300 | D4: 230 | E4: =[1]Sayfa3!C7 -> 0.62 | F4: 94.995 | G4: =[1]Sayfa3!F7 -> 70000 | H4: 49.16 | I4: 2.92 | J4: 20 | K4: 21 | L4: 130 | M4: 12.175 | N4: 10
C5: SANTAL AYLIK KİRA BEDELİ | D5: MİKSER AYLIK KİRA BEDELİ | E5: POMPA AYLIK KİRA BEDELİ | F5: LOADER AYLIK KİRA BEDELİ | G5: SERVİS ARAÇ AYLIK BEDELİ
C6: 400000 | D6: 250000 | E6: 450000 | F6: 200000 | G6: 40000
C8: C 16 | E8: C 20 | G8: C 25 | I8: C 30 | K8: C 35 | M8: C 40
C9: MİKTAR | D9: TUTAR | E9: MİKTAR | F9: TUTAR | G9: MİKTAR | H9: TUTAR | I9: MİKTAR | J9: TUTAR | K9: MİKTAR | L9: TUTAR | M9: MİKTAR | N9: TUTAR
B10: ÇİMENTO | C10: 170 | D10: =C10*C4/1000 -> 731 | E10: 230 | F10: =E10*C4/1000 -> 989 | G10: 300 | H10: =G10*C4/1000 -> 1290 | I10: 340 | J10: =I10*C4/1000 -> 1462 | K10: 370 | L10: =K10*C4/1000 -> 1591 | M10: 410 | N10: =M10*C4/1000 -> 1763
B11: AGREGA | C11: 1940 | D11: =C11*D4/1000 -> 446.2 | E11: 1868.4 | F11: =E11*D4/1000 -> 429.732 | G11: 1939 | H11: =G11*D4/1000 -> 445.97 | I11: 1892 | J11: =I11*D4/1000 -> 435.16 | K11: 1859 | L11: =K11*D4/1000 -> 427.57 | M11: 1819 | N11: =M11*D4/1000 -> 418.37
B12: KATKI | C12: 1.9 | D12: =C12*E4*H4 -> 57.91048 | E12: =E10*1/100 -> 2.3 | F12: =E12*H4*E4 -> 70.10216 | G12: =G10*1/100 -> 3 | H12: =G12*E4*H4 -> 91.4376 | I12: =I10*1/100 -> 3.4 | J12: =I12*E4*H4 -> 103.62928 | K12: =K10*1/100 -> 3.7 | L12: =K12*E4*H4 -> 112.77304 | M12: =M10*1/100 -> 4.1 | N12: =M12*E4*H4 -> 124.96472
B13: MİKSER MOTORİN | C13: =IF($C$2="SANTRAL ALTI",0,0.7*2*J4/N4) -> 2.8 | D13: =C13*F4 -> 265.986 | E13: =IF($C$2="SANTRAL ALTI",0,0.7*2*J4/N4) -> 2.8 | F13: =E13*F4 -> 265.986 | G13: =IF($C$2="SANTRAL ALTI",0,0.7*2*J4/N4) -> 2.8 | H13: =G13*F4 -> 265.986 | I13: =IF($C$2="SANTRAL ALTI",0,0.7*2*J4/N4) -> 2.8 | J13: =I13*F4 -> 265.986 | K13: =IF($C$2="SANTRAL ALTI",0,0.7*2*J4/N4) -> 2.8 | L13: =K13*F4 -> 265.986 | M13: =IF($C$2="SANTRAL ALTI",0,0.7*2*J4/N4) -> 2.8 | N13: =M13*F4 -> 265.986
B14: AGREGA NAKLİYE | C14: =0.4*2*K4/38 -> 0.44210526 | D14: =C14*F4*C11/1000*1.15 -> 93.697068 | E14: =0.4*2*K4/38 -> 0.44210526 | F14: =E14*F4*E11/1000*1.15 -> 90.23897 | G14: =0.4*2*K4/38 -> 0.44210526 | H14: =G14*F4*G11/1000*1.15 -> 93.648771 | I14: =0.4*2*K4/38 -> 0.44210526 | J14: =I14*F4*I11/1000*1.15 -> 91.37879 | K14: =0.4*2*K4/38 -> 0.44210526 | L14: =K14*F4*K11/1000*1.15 -> 89.784974 | M14: =0.4*2*K4/38 -> 0.44210526 | N14: =M14*F4*M11/1000*1.15 -> 87.853076
B15: POMPA MOTORİN | C15: =IF($C$2="POMPALI",0.73,0) -> 0.73 | D15: =C15*F4 -> 69.34635 | E15: =IF($C$2="POMPALI",0.73,0) -> 0.73 | F15: =E15*F4 -> 69.34635 | G15: =IF($C$2="POMPALI",0.73,0) -> 0.73 | H15: =G15*F4 -> 69.34635 | I15: =IF($C$2="POMPALI",0.73,0) -> 0.73 | J15: =I15*F4 -> 69.34635 | K15: =IF($C$2="POMPALI",0.73,0) -> 0.73 | L15: =K15*F4 -> 69.34635 | M15: =IF($C$2="POMPALI",0.73,0) -> 0.73 | N15: =M15*F4 -> 69.34635
B16: KEPÇE MOTORİN | C16: 0.35 | D16: =C16*F4 -> 33.24825 | E16: 0.35 | F16: =E16*F4 -> 33.24825 | G16: 0.35 | H16: =G16*F4 -> 33.24825 | I16: 0.35 | J16: =I16*F4 -> 33.24825 | K16: 0.35 | L16: =K16*F4 -> 33.24825 | M16: 0.35 | N16: =M16*F4 -> 33.24825
B17: İŞÇİLİK | C17: 21 | D17: =G4*C17/30/L4 -> 376.92308 | E17: 21 | F17: =G4*E17/30/L4 -> 376.92308 | G17: 21 | H17: =G17*G4/30/L4 -> 376.92308 | I17: 21 | J17: =I17*G4/30/L4 -> 376.92308 | K17: 21 | L17: =K17*G4/30/L4 -> 376.92308 | M17: 21 | N17: =M17*G4/30/L4 -> 376.92308
B18: ELEKTRİK(KWH) | C18: 5.5 | D18: =C18*I4 -> 16.06 | E18: 5.5 | F18: =E18*I4 -> 16.06 | G18: 5.5 | H18: =G18*I4 -> 16.06 | I18: 5.5 | J18: =I18*I4 -> 16.06 | K18: 5.5 | L18: =K18*I4 -> 16.06 | M18: 5.5 | N18: =M18*I4 -> 16.06
B19: SU | C19: 1 | D19: =C19*M4 -> 12.175 | E19: 1 | F19: =M4*E19 -> 12.175 | G19: 1 | H19: =G19*M4 -> 12.175 | I19: 1 | J19: =I19*M4 -> 12.175 | K19: 1 | L19: =K19*M4 -> 12.175 | M19: 1 | N19: =M19*M4 -> 12.175
B20: DİĞER (%5) | D20: =SUM(D10:D19)*0.05 -> 105.12731 | F20: =SUM(F10:F19)*0.05 -> 117.64059 | H20: =SUM(H10:H19)*0.05 -> 134.73975 | J20: =SUM(J10:J19)*0.05 -> 143.29534 | L20: =SUM(L10:L19)*0.05 -> 149.74333 | N20: =SUM(N10:N19)*0.05 -> 158.39632
C21: ARA TOPLAM | D21: =SUM(D10:D20) -> 2207.6735 | E21: ARA TOPLAM | F21: =SUM(F10:F20) -> 2470.4524 | G21: ARA TOPLAM | H21: =SUM(H10:H20) -> 2829.5348 | I21: ARA TOPLAM | J21: =SUM(J10:J20) -> 3009.2021 | K21: ARA TOPLAM | L21: =SUM(L10:L20) -> 3144.61 | M21: ARA TOPLAM | N21: =SUM(N10:N20) -> 3326.3228
B22: MİKSER KİRA BEDELİ | C22: 4 | D22: =C22*D6/30/L4 -> 256.41026 | E22: 4 | F22: =C22*D6/30/L4 -> 256.41026 | G22: 4 | H22: =C22*D6/30/L4 -> 256.41026 | I22: 4 | J22: =C22*D6/30/L4 -> 256.41026 | K22: 4 | L22: =C22*D6/30/L4 -> 256.41026 | M22: 4 | N22: =C22*D6/30/L4 -> 256.41026
B23: POMPA KİRA BEDELİ | C23: 1 | D23: =C23*E6/30/L4 -> 115.38462 | E23: 1 | F23: =C23*E6/30/L4 -> 115.38462 | G23: 1 | H23: =C23*E6/30/L4 -> 115.38462 | I23: 1 | J23: =C23*E6/30/L4 -> 115.38462 | K23: 1 | L23: =C23*E6/30/L4 -> 115.38462 | M23: 1 | N23: =C23*E6/30/L4 -> 115.38462
B24: LOADER KİRA BEDELİ | C24: 1 | D24: =C24*F6/30/L4 -> 51.282051 | E24: 1 | F24: =C24*F6/30/L4 -> 51.282051 | G24: 1 | H24: =C24*F6/30/L4 -> 51.282051 | I24: 1 | J24: =C24*F6/30/L4 -> 51.282051 | K24: 1 | L24: =C24*F6/30/L4 -> 51.282051 | M24: 1 | N24: =C24*F6/30/L4 -> 51.282051
B25: SANTRAL KİRA BEDELİ | C25: 1 | D25: =C25*C6/30/L4 -> 102.5641 | E25: 1 | F25: =C25*C6/30/L4 -> 102.5641 | G25: 1 | H25: =C25*C6/30/L4 -> 102.5641 | I25: 1 | J25: =C25*C6/30/L4 -> 102.5641 | K25: 1 | L25: =C25*C6/30/L4 -> 102.5641 | M25: 1 | N25: =C25*C6/30/L4 -> 102.5641
B26: SERVİS ARAÇ KİRA BEDELİ | C26: 1 | D26: =C26*G6/30/L4 -> 10.25641 | E26: 1 | F26: =C26*G6/30/L4 -> 10.25641 | G26: 1 | H26: =C26*G6/30/L4 -> 10.25641 | I26: 1 | J26: =C26*G6/30/L4 -> 10.25641 | K26: 1 | L26: =C26*G6/30/L4 -> 10.25641 | M26: 1 | N26: =C26*G6/30/L4 -> 10.25641
B27: DİĞER (%5) | D27: =(SUM(D10:D26)-D21-D20)*0.05 -> 131.92218 | F27: =(SUM(F10:F26)-F21-F20)*0.05 -> 144.43546 | H27: =(SUM(H10:H26)-H21-H20)*0.05 -> 161.53462 | J27: =(SUM(J10:J26)-J21-J20)*0.05 -> 170.09021 | L27: =(SUM(L10:L26)-L21-L20)*0.05 -> 176.53821 | N27: =(SUM(N10:N26)-N21-N20)*0.05 -> 185.1912
C28: GENEL TOPLAM | D28: =SUM(D10:D27)-D21-D20 -> 2770.3658 | E28: GENEL TOPLAM | F28: =SUM(F10:F27)-F21-F20 -> 3033.1447 | G28: GENEL TOPLAM | H28: =SUM(H10:H27)-H21-H20 -> 3392.2271 | I28: GENEL TOPLAM | J28: =SUM(J10:J27)-J21-J20 -> 3571.8944 | K28: GENEL TOPLAM | L28: =SUM(L10:L27)-L21-L20 -> 3707.3023 | M28: GENEL TOPLAM | N28: =SUM(N10:N27)-N21-N20 -> 3889.0151
B30: *ELEKTRİK: 1M³ BETON İÇİN 5,5KWH
B31: *MİKSER: 0,70 L/KM
B32: *AGREGA KAMYONU : 0,40 L/KM
B33: *KEPÇE : 0,35 L/M³
B34: *POMPA : 0,73 L/M³
B35: *AGREGA OCAK MALİYETİ 200 TL (AGREGA FİYATI VE NAKLİYE MOTORİN FİYATI BOLVADİN TESLİM %15 KARLI HESAPLANMIŞTIR)
B36: *SU: BETON SUYU + YIKAMA 1 TON (BELEDİYE FİYATI KDV DAHİL 14,61)
B37: *SARI ALANLARA DEĞER GİRİNİZ.

Sheet Hesaplama
B1: BETON MALİYET HESAPLAMA (Arka Plan) - Girdileri Dashboard sayfasından değiştiriniz
B3: GİRDİLER (Dashboard bağlantılı) | E3: SABİT PARAMETRELER
B4: Çimento (TL/ton) | C4: =Dashboard!C8 -> 4300 | E4: Mikser yakıt tüketimi (L/km) | F4: 0.7
B5: Agrega (TL/ton) | C5: =Dashboard!C9 -> 200 | E5: Agrega kamyonu yakıt (L/km) | F5: 0.4
B6: Katkı ($/kg) | C6: =Dashboard!C10 -> 0.62 | E6: Agrega kamyon kapasitesi (ton) | F6: 38
B7: Mazot (TL/L) | C7: =Dashboard!C12 -> 94.995 | E7: Agrega nakliye kâr payı | F7: 0.15
B8: Ort. İşçilik (TL/kişi/ay) | C8: =Dashboard!C15 -> 70000 | E8: Pompa motorin (L/m³) | F8: 0.73
B9: Dolar/TL | C9: =Dashboard!C11 -> 49.16 | E9: Kepçe motorin (L/m³) | F9: 0.35
B10: Elektrik (TL/kWh) | C10: =Dashboard!C13 -> 2.92 | E10: İşçi sayısı | F10: 21
B11: Su (TL/ton) | C11: =Dashboard!C14 -> 12.175 | E11: Elektrik tüketimi (kWh/m³) | F11: 5.5
B12: Döküm Mesafesi (km) | C12: =Dashboard!C18 -> 24 | E12: Su tüketimi (ton/m³) | F12: 1
B13: Agrega Taşıma Mesafesi (km) | C13: =Dashboard!C19 -> 21 | E13: Diğer gider oranı | F13: 0.05
B14: Günlük Döküm (m³) | C14: =Dashboard!C20 -> 140 | E14: Mikser adedi | F14: 4
B15: Mikser Kapasitesi (m³) | C15: =Dashboard!C21 -> 10 | E15: Pompa adedi | F15: 1
B16: Santral Kira (TL/ay) | C16: =Dashboard!C24 -> 0 | E16: Loader adedi | F16: 1
B17: Mikser Kira (TL/ay) | C17: =Dashboard!C25 -> 0 | E17: Santral adedi | F17: 1
B18: Pompa Kira (TL/ay) | C18: =Dashboard!C26 -> 0 | E18: Servis aracı adedi | F18: 1
B19: Loader Kira (TL/ay) | C19: =Dashboard!C27 -> 0 | E19: Aylık gün sayısı | F19: 30
B20: Servis Aracı Kira (TL/ay) | C20: =Dashboard!C28 -> 0 | E20: Katkı oranı (çimentonun %) | F20: 0.01
B22: REÇETE VE MALİYET HESABI (TL/m³)
B23: Kalem | C23: C 16 | D23: C 20 | E23: C 25 | F23: C 30 | G23: C 35 | H23: C 40
B24: Çimento (kg/m³) | C24: 170 | D24: 230 | E24: 300 | F24: 340 | G24: 370 | H24: 410
B25: Agrega (kg/m³) | C25: 1940 | D25: 1868.4 | E25: 1939 | F25: 1892 | G25: 1859 | H25: 1819
B26: Katkı (kg/m³) | C26: 1.9 | D26: =D24*$F$20 -> 2.3 | E26: =E24*$F$20 -> 3 | F26: =F24*$F$20 -> 3.4 | G26: =G24*$F$20 -> 3.7 | H26: =H24*$F$20 -> 4.1
B27: Birim Maliyetler (TL/m³)
B28: Çimento | C28: =C24*$C$4/1000 -> 731 | D28: =D24*$C$4/1000 -> 989 | E28: =E24*$C$4/1000 -> 1290 | F28: =F24*$C$4/1000 -> 1462 | G28: =G24*$C$4/1000 -> 1591 | H28: =H24*$C$4/1000 -> 1763
B29: Agrega | C29: =C25*$C$5/1000 -> 388 | D29: =D25*$C$5/1000 -> 373.68 | E29: =E25*$C$5/1000 -> 387.8 | F29: =F25*$C$5/1000 -> 378.4 | G29: =G25*$C$5/1000 -> 371.8 | H29: =H25*$C$5/1000 -> 363.8
B30: Katkı | C30: =C26*$C$6*$C$9 -> 57.91048 | D30: =D26*$C$6*$C$9 -> 70.10216 | E30: =E26*$C$6*$C$9 -> 91.4376 | F30: =F26*$C$6*$C$9 -> 103.62928 | G30: =G26*$C$6*$C$9 -> 112.77304 | H30: =H26*$C$6*$C$9 -> 124.96472
B31: Agrega Nakliye | C31: =$F$5*2*$C$13/$F$6*$C$7*C25/1000*(1+$F$7) -> 93.697068 | D31: =$F$5*2*$C$13/$F$6*$C$7*D25/1000*(1+$F$7) -> 90.23897 | E31: =$F$5*2*$C$13/$F$6*$C$7*E25/1000*(1+$F$7) -> 93.648771 | F31: =$F$5*2*$C$13/$F$6*$C$7*F25/1000*(1+$F$7) -> 91.37879 | G31: =$F$5*2*$C$13/$F$6*$C$7*G25/1000*(1+$F$7) -> 89.784974 | H31: =$F$5*2*$C$13/$F$6*$C$7*H25/1000*(1+$F$7) -> 87.853076
B32: Kepçe Motorin | C32: =$F$9*$C$7 -> 33.24825 | D32: =$F$9*$C$7 -> 33.24825 | E32: =$F$9*$C$7 -> 33.24825 | F32: =$F$9*$C$7 -> 33.24825 | G32: =$F$9*$C$7 -> 33.24825 | H32: =$F$9*$C$7 -> 33.24825
B33: İşçilik | C33: =$F$10*$C$8/$F$19/$C$14 -> 350 | D33: =$F$10*$C$8/$F$19/$C$14 -> 350 | E33: =$F$10*$C$8/$F$19/$C$14 -> 350 | F33: =$F$10*$C$8/$F$19/$C$14 -> 350 | G33: =$F$10*$C$8/$F$19/$C$14 -> 350 | H33: =$F$10*$C$8/$F$19/$C$14 -> 350
B34: Elektrik | C34: =$F$11*$C$10 -> 16.06 | D34: =$F$11*$C$10 -> 16.06 | E34: =$F$11*$C$10 -> 16.06 | F34: =$F$11*$C$10 -> 16.06 | G34: =$F$11*$C$10 -> 16.06 | H34: =$F$11*$C$10 -> 16.06
B35: Su | C35: =$F$12*$C$11 -> 12.175 | D35: =$F$12*$C$11 -> 12.175 | E35: =$F$12*$C$11 -> 12.175 | F35: =$F$12*$C$11 -> 12.175 | G35: =$F$12*$C$11 -> 12.175 | H35: =$F$12*$C$11 -> 12.175
B36: Mikser Kira | C36: =$F$14*$C$17/$F$19/$C$14 -> 0 | D36: =$F$14*$C$17/$F$19/$C$14 -> 0 | E36: =$F$14*$C$17/$F$19/$C$14 -> 0 | F36: =$F$14*$C$17/$F$19/$C$14 -> 0 | G36: =$F$14*$C$17/$F$19/$C$14 -> 0 | H36: =$F$14*$C$17/$F$19/$C$14 -> 0
B37: Pompa Kira | C37: =$F$15*$C$18/$F$19/$C$14 -> 0 | D37: =$F$15*$C$18/$F$19/$C$14 -> 0 | E37: =$F$15*$C$18/$F$19/$C$14 -> 0 | F37: =$F$15*$C$18/$F$19/$C$14 -> 0 | G37: =$F$15*$C$18/$F$19/$C$14 -> 0 | H37: =$F$15*$C$18/$F$19/$C$14 -> 0
B38: Loader Kira | C38: =$F$16*$C$19/$F$19/$C$14 -> 0 | D38: =$F$16*$C$19/$F$19/$C$14 -> 0 | E38: =$F$16*$C$19/$F$19/$C$14 -> 0 | F38: =$F$16*$C$19/$F$19/$C$14 -> 0 | G38: =$F$16*$C$19/$F$19/$C$14 -> 0 | H38: =$F$16*$C$19/$F$19/$C$14 -> 0
B39: Santral Kira | C39: =$F$17*$C$16/$F$19/$C$14 -> 0 | D39: =$F$17*$C$16/$F$19/$C$14 -> 0 | E39: =$F$17*$C$16/$F$19/$C$14 -> 0 | F39: =$F$17*$C$16/$F$19/$C$14 -> 0 | G39: =$F$17*$C$16/$F$19/$C$14 -> 0 | H39: =$F$17*$C$16/$F$19/$C$14 -> 0
B40: Servis Aracı Kira | C40: =$F$18*$C$20/$F$19/$C$14 -> 0 | D40: =$F$18*$C$20/$F$19/$C$14 -> 0 | E40: =$F$18*$C$20/$F$19/$C$14 -> 0 | F40: =$F$18*$C$20/$F$19/$C$14 -> 0 | G40: =$F$18*$C$20/$F$19/$C$14 -> 0 | H40: =$F$18*$C$20/$F$19/$C$14 -> 0
B41: Ortak Maliyet Ara Toplam | C41: =SUM(C28:C40) -> 1682.0908 | D41: =SUM(D28:D40) -> 1934.5044 | E41: =SUM(E28:E40) -> 2274.3696 | F41: =SUM(F28:F40) -> 2446.8913 | G41: =SUM(G28:G40) -> 2576.8413 | H41: =SUM(H28:H40) -> 2751.101
B42: Mikser Motorin (Pompalı + Mikserli) | C42: =$F$4*2*$C$12/$C$15*$C$7 -> 319.1832 | D42: =$F$4*2*$C$12/$C$15*$C$7 -> 319.1832 | E42: =$F$4*2*$C$12/$C$15*$C$7 -> 319.1832 | F42: =$F$4*2*$C$12/$C$15*$C$7 -> 319.1832 | G42: =$F$4*2*$C$12/$C$15*$C$7 -> 319.1832 | H42: =$F$4*2*$C$12/$C$15*$C$7 -> 319.1832
...
